<mujoco model="Fish3D_Swimmer">
    <!--
    3D Fish/Snake Robot for LBM-MuJoCo Coupled Simulation
    
    Structure:
    - head: root body with a free joint and 6 DOF
    - body: middle segment with a hinge around z
    - tail: tail segment with a hinge around z
    
    Control:
    - joint1: head-body joint, torque range [-1, 1]
    - joint2: body-tail joint, torque range [-1, 1]
    -->
    
    <compiler angle="degree" inertiafromgeom="true"/>
    <option timestep="0.001" gravity="0 0 0" integrator="RK4"/>
    
    <default>
        <joint damping="0.1" stiffness="0" armature="0.01"/>
        <motor ctrlrange="-1 1" ctrllimited="true"/>
        <geom solref="0.001 1" solimp="0.9 0.95 0.001"/>
    </default>
    
    <asset>
        <material name="head_mat" rgba="0.2 0.6 0.9 1"/>
        <material name="body_mat" rgba="0.4 0.8 1.0 1"/>
        <material name="tail_mat" rgba="0.6 1.0 1.0 1"/>
    </asset>
    
    <worldbody>
        <!-- Root head with a free joint and 6 DOF. -->
        <body name="head" pos="0 0 0">
            <freejoint name="root_joint"/>
            
        <!-- Streamlined ellipsoid head. -->
            <geom name="head_geom" type="ellipsoid"
                  size="0.084 0.126 0.063"
                  pos="0 0 0"
                  material="head_mat"
                  density="500"/>
            
            <!-- Mid-body with three independent hinge joints. -->
            <body name="body" pos="0 -0.147 0">
                <!-- Pitch around x. -->
                <joint name="joint1_pitch" type="hinge" axis="1 0 0" limited="true" range="-15 15"/>
                <!-- Roll around y. -->
                <joint name="joint1_roll" type="hinge" axis="0 1 0" limited="true" range="-10 10"/>
                <!-- Propulsive yaw around z. -->
                <joint name="joint1_yaw" type="hinge" axis="0 0 1" limited="true" range="-60 60"/>
                
                <!-- Ellipsoid body geometry. -->
                <geom name="body_geom" type="ellipsoid"
                      size="0.074 0.105 0.053"
                      pos="0 0 0"
                      material="body_mat"
                      density="500"/>
                
                <!-- Tail with three independent hinge joints. -->
                <body name="tail" pos="0 -0.126 0">
                    <!-- Pitch around x. -->
                    <joint name="joint2_pitch" type="hinge" axis="1 0 0" limited="true" range="-15 15"/>
                    <!-- Roll around y. -->
                    <joint name="joint2_roll" type="hinge" axis="0 1 0" limited="true" range="-10 10"/>
                    <!-- Main tail yaw around z. -->
                    <joint name="joint2_yaw" type="hinge" axis="0 0 1" limited="true" range="-60 60"/>
                    
                    <!-- Slender tail peduncle. -->
                    <geom name="tail_stem" type="capsule"
                          fromto="0 0 0 0 -0.084 0"
                          size="0.032"
                          material="tail_mat"
                          density="500"/>
                    
                    <!-- Flat vertical tail fin for lateral propulsion. -->
                    <geom name="tail_fin" type="ellipsoid"
                          size="0.017 0.053 0.084"
                          pos="0 -0.105 0"
                          material="tail_mat"
                          density="500"/>
                </body>
            </body>
        </body>
    </worldbody>
    
    <actuator>
        <!-- Joint 1: head to body. -->
        <motor name="motor1_pitch" joint="joint1_pitch" gear="10" ctrlrange="-1 1"/>
        <motor name="motor1_roll" joint="joint1_roll" gear="10" ctrlrange="-1 1"/>
        <motor name="motor1_yaw" joint="joint1_yaw" gear="40" ctrlrange="-1 1"/>
        <!-- Joint 2: body to tail. -->
        <motor name="motor2_pitch" joint="joint2_pitch" gear="10" ctrlrange="-1 1"/>
        <motor name="motor2_roll" joint="joint2_roll" gear="10" ctrlrange="-1 1"/>
        <motor name="motor2_yaw" joint="joint2_yaw" gear="40" ctrlrange="-1 1"/>
    </actuator>
</mujoco>
