<mujoco model="SerialFish3D">
    <!--
    Serial multi-joint robotic fish with pitch control.
    Design:
    - Rigid head shell containing electronics
    - Three servo-driven body segments
    - Rigid fan-shaped tail fin
    
    Total length is about 0.4 m for the LBM grid.
    Coordinates: x right, y forward, z up.
    
    Joint configuration:
    - seg1_pitch controls ascent and descent.
    - seg1_yaw through tail_yaw control lateral motion.
    -->
    
    <compiler angle="degree" inertiafromgeom="true"/>
    <option timestep="0.01" gravity="0 0 0" integrator="RK4"/>
    
    <default>
        <joint damping="0.1" stiffness="0" armature="0.01"/>
        <motor ctrlrange="-1 1" ctrllimited="true"/>
        <geom solref="0.001 1" solimp="0.9 0.95 0.001"/>
    </default>
    
    <asset>
        <material name="head_mat" rgba="0.8 0.2 0.2 1"/>       <!-- Red head. -->
        <material name="body_mat" rgba="0.3 0.3 0.3 1"/>       <!-- Dark gray body. -->
        <material name="tail_mat" rgba="0.9 0.7 0.2 1"/>       <!-- Golden tail fin. -->
    </asset>
    
    <worldbody>
        <!-- Root head with a free joint. -->
        <body name="head" pos="0 0 0">
            <freejoint name="root_joint"/>
            
            <!-- Streamlined ellipsoid head shell. -->
            <geom name="head_shell" type="ellipsoid"
                  size="0.04 0.06 0.03"
                  pos="0 0 0"
                  material="head_mat"
                  density="1500"/>
            
            <!-- Body segment 1. -->
            <!-- Rear of head at y=-0.06. -->
            <body name="body_seg1" pos="0 -0.06 0">
                <!-- Pitch around x for vertical motion. -->
                <!-- Negative x makes positive values pitch upward. -->
                <joint name="seg1_pitch" type="hinge" axis="-1 0 0"
                       limited="true" range="-25 25"/>
                <!-- Yaw around z for lateral motion. -->
                <joint name="seg1_yaw" type="hinge" axis="0 0 1" 
                       limited="true" range="-30 30"/>
                
                <!-- box half-size Y=0.04 -->
                <geom name="seg1_geom" type="box"
                      size="0.035 0.04 0.025"
                      pos="0 -0.04 0"
                      material="body_mat"
                      density="1200"/>
                
                <!-- Body segment 2. -->
                <!-- Segment 1 rear is y=-0.08 from the joint. -->
                <body name="body_seg2" pos="0 -0.08 0">
                    <joint name="seg2_yaw" type="hinge" axis="0 0 1"
                           limited="true" range="-30 30"/>
                    
                    <geom name="seg2_geom" type="box"
                          size="0.033 0.04 0.023"
                          pos="0 -0.04 0"
                          material="body_mat"
                          density="1200"/>
                    
                    <!-- Body segment 3. -->
                    <!-- Segment 2 rear is y=-0.08 from the joint. -->
                    <body name="body_seg3" pos="0 -0.08 0">
                        <joint name="seg3_yaw" type="hinge" axis="0 0 1"
                               limited="true" range="-35 35"/>
                        
                        <geom name="seg3_geom" type="box"
                              size="0.030 0.035 0.020"
                              pos="0 -0.035 0"
                              material="body_mat"
                              density="1200"/>
                        
                        <!-- Tail peduncle. -->
                        <!-- Segment 3 rear is y=-0.07 from the joint. -->
                        <body name="tail_peduncle" pos="0 -0.07 0">
                            <joint name="tail_yaw" type="hinge" axis="0 0 1"
                                   limited="true" range="-45 45"/>
                            
                            <!-- Capsule peduncle extends behind the joint. -->
                            <geom name="peduncle_geom" type="capsule"
                                  fromto="0 0 0 0 -0.05 0"
                                  size="0.015"
                                  material="body_mat"
                                  density="1100"/>
                            
                            <!-- Caudal fin. -->
                            <!-- Capsule rear is y=-0.05. -->
                            <body name="tail_fin" pos="0 -0.05 0">
                                <!-- Tail fin attached to the peduncle. -->
                                <geom name="tail_fin_geom" type="ellipsoid"
                                      size="0.002 0.04 0.05"
                                      pos="0 -0.04 0"
                                      material="tail_mat"
                                      density="800"/>
                            </body>
                        </body>
                    </body>
                </body>
            </body>
        </body>
        
        <light directional="true" diffuse="0.9 0.9 0.9" pos="0 0 3" dir="0 0 -1"/>
    </worldbody>
    
    <actuator>
        <!-- 
        Five controlled joints:
        - One pitch joint for vertical motion
        - Four yaw joints for lateral swimming
        -->
        <motor name="motor_pitch" joint="seg1_pitch" gear="0.5" ctrlrange="-1 1"/>
        <motor name="motor_seg1" joint="seg1_yaw" gear="0.5" ctrlrange="-1 1"/>
        <motor name="motor_seg2" joint="seg2_yaw" gear="0.4" ctrlrange="-1 1"/>
        <motor name="motor_seg3" joint="seg3_yaw" gear="0.3" ctrlrange="-1 1"/>
        <motor name="motor_tail" joint="tail_yaw" gear="0.2" ctrlrange="-1 1"/>
    </actuator>
</mujoco>
