<mujoco model="Snake">

    <compiler angle="degree" inertiafromgeom="true"/>

    <default>
        <motor ctrlrange="-1 1" ctrllimited="true"/>
    </default>

    <!-- <custom>
        <numeric name="ls_parallel" data="1"/>
    </custom> -->

    <option timestep="1.0" integrator="RK4" gravity="0 0 0" tolerance="1e-6" />
    	
    <asset>
        <texture name="texplane" type="2d" builtin="checker" rgb1="0.2 0.3 0.4" rgb2="0.1 0.15 0.2" width="512" height="512"/>
        <material name="matplane" reflectance="0.3" texture="texplane" texrepeat="1 1" texuniform="true"/>
        <material name="segment1" rgba="1.0 0.2 0.2 1"/>  <!-- Red. -->
        <material name="segment2" rgba="0.2 1.0 0.2 1"/>  <!-- Green. -->
        <material name="segment3" rgba="0.2 0.2 1.0 1"/>  <!-- Blue. -->
    </asset>

    <worldbody>
        <!-- Ground plane. -->
        <geom name="floor" pos="0 0 0" size="5 5 0.1" type="plane" material="matplane" friction="0.0 0.000 0.0000"/>
        
        <!-- Light source. -->
        <light directional="true" diffuse="0.8 0.8 0.8" specular="0.2 0.2 0.2" pos="0 0 5" dir="0 0 -1"/>

        <!-- Center body with inward-offset wings. -->
        <body name="center" pos="0 0 0.55">
            <!-- The free joint allows translation and rotation. -->
            <joint name="center_free" type="free" damping="0.0" stiffness="0" armature="0.0"/>
            
            <!-- Center block. -->
            <geom name="center_body" type="box" size="0.05 0.05 0.05" material="segment3" density="40000000"/>
            
            <!-- Left wing hinged at the edge. -->
            <body name="left_wing" pos="-0.344 0 0">
                <!-- Hinge at the center block's left edge. -->
                <joint name="joint_left" type="hinge" pos="0.344 0 0" axis="0 0 1" range="-60 60" damping="0.001" stiffness="0" armature="0.0"/>
                <geom name="left_wing_geom" type="box" size="0.3 0.025 0.05" material="segment1" density="100000"/>
            </body>
            
            <!-- Right wing hinged at the edge. -->
            <body name="right_wing" pos="0.344 0 0">
                <!-- Hinge at the center block's right edge. -->
                <joint name="joint_right" type="hinge" pos="-0.344 0 0" axis="0 0 1" range="-60 60" damping="0.001" stiffness="0" armature="0.0"/>
                <geom name="right_wing_geom" type="box" size="0.3 0.025 0.05" material="segment2" density="100000"/>
            </body>
        </body>
    </worldbody>

    <actuator>
        <!-- Joint motors. -->
        <motor name="motor_left" joint="joint_left" gear="0.2"/>
        <motor name="motor_right" joint="joint_right" gear="0.2"/>
    </actuator>

</mujoco>
