<mujoco model="Fish2D_Swimmer">

    <compiler angle="degree" inertiafromgeom="true"/>
    <option timestep="0.01" gravity="0 0 0" integrator="RK4"/>

    <default>
        <joint damping="0.05" stiffness="0" armature="0.01"/>
        <motor ctrlrange="-1 1" ctrllimited="true"/>
        <geom solref="0.001 1" solimp="0.9 0.95 0.001"/>
    </default>

    <asset>
        <material name="head"    rgba="0.2 0.6 0.9 1"/>
        <material name="body"    rgba="0.4 0.8 1.0 1"/>
        <material name="tail"    rgba="0.6 1.0 1.0 1"/>
    </asset>

    <worldbody>
        <geom type="plane" size="5 5 0.1" material="head" rgba="0.1 0.1 0.1 1" pos="0 0 0"/>

        <body name="root" pos="0 0 0.05">
            <joint name="free_xy" type="free"/>

            <!-- 头部：圆形头部，流线型 -->
            <geom name="head_geom" type="capsule"
                  fromto="0 0 0  0 -0.1 0"
                  size="0.04"
                  material="head"
                  density="500"/>

            <!-- 身体中段 -->
            <body name="body" pos="0 -0.1 0">
                <joint name="joint1" type="hinge" axis="0 0 1" range="-45 45"/>
                
                <geom name="body_geom" type="capsule"
                      fromto="0 0 0  0 -0.1 0"
                      size="0.035"
                      material="body"
                      density="500"/>

                <!-- 尾部：尾柄 + 宽尾鳍，LBM中会合并为凸包形成锥形 -->
                <body name="tail" pos="0 -0.1 0">
                    <joint name="joint2" type="hinge" axis="0 0 1" range="-60 60"/>

                    <!-- 尾柄：细长连接段 -->
                    <geom name="tail_stem" type="capsule"
                          fromto="0 0 0  0 -0.08 0"
                          size="0.02"
                          material="tail"
                          density="500"/>

                    <!-- 尾鳍：宽大的推水面 -->
                    <geom name="tail_fin" type="ellipsoid"
                          size="0.06 0.04 0.02"
                          pos="0 -0.1 0"
                          material="tail"
                          density="500"/>
                </body>
            </body>
        </body>
        <light directional="true" diffuse="0.9 0.9 0.9" pos="0 0 5" dir="0 0 -1"/>
    </worldbody>

    <actuator>
        <motor joint="joint1" gear="0.15"/>
        <motor joint="joint2" gear="0.2"/>
    </actuator>

</mujoco>
